Workbook
Name Fertilizers\Fertilizer: Fertilizers[Fertilizer]
Name Fertilizers\Fertilizer: Fertilizers[Fertilizer]
Name Jars\Jar: Jars[Jar]
Name List\Elements: List[Elements]
Name List\Fertilizers: List[Fertilizers]
Name List\Nutrients: List[Nutrients]
Name List\Root_Color: List[Root Color]
Name List\Root_Texture: List[Root Texture]
Name List\Solutions: List[Solutions]
Name Nutrients\For: Nutrients[For]
Name Nutrients\For: Nutrients[For]
Name Seeds\Scientific_Name: Seeds[Scientific Name]
Name Seeds\Scientific_Name: Seeds[Scientific Name]
Name Solutions\Name: Solutions[Name]
Name Solutions\Name: Solutions[Name]

Sheet Data Validation
A10: Solutions | B10: Fertilizers | C10: Nutrients | D10: Elements | E10: Concentration Units | F10: Seasons | G10: Root Color | H10: Root Texture
A11: EC (min) | B11: N (%) | C11: N (ppm) | D11: N | E11: ppm | F11: Year-Round | G11: Unknown | H11: Unknown
A12: EC (max) | B12: P (%) | C12: P (ppm) | D12: P | E12: µM | F12: Spring | G12: White | H12: Firm
A13: pH (min) | B13: K (%) | C13: K (ppm) | D13: K | F13: Summer | G13: Off White | H13: Soft
A14: pH (max) | B14: Ca (%) | C14: Ca (ppm) | D14: Ca | F14: Fall | G14: Grayish | H14: Mushy
A15: N | B15: Mg (%) | C15: Mg (ppm) | D15: Mg | F15: Winter | G15: Light Brown | H15: Slimey
A16: P | B16: S (%) | C16: S (ppm) | D16: S | G16: Brown
A17: K | B17: B (%) | C17: B (ppm) | D17: B | G17: Dark Brown
A18: Ca | B18: Cu (%) | C18: Cu (ppm) | D18: Cu | G18: Blackish
A19: Mg | B19: Fe (%) | C19: Fe (ppm) | D19: Fe
A20: S | B20: Mn (%) | C20: Mn (ppm) | D20: Mn
A21: B | B21: Mo (%) | C21: Mo (ppm) | D21: Mo
A22: Cu | B22: Zn (%) | C22: Zn (ppm) | D22: Zn
A23: Fe | B23: Ni (%) | C23: Ni (ppm) | D23: Ni
A24: Mn | B24: Cl (%) | C24: Cl (ppm) | D24: Cl
A25: Mo | B25: Na (%) | C25: Na (ppm) | D25: Na
A26: Zn | B26: Si (%) | C26: Si (ppm) | D26: Si
A27: Ni | B27: Co (%) | C27: Co (ppm) | D27: Co
A28: Cl | B28: I (%) | C28: I (ppm) | D28: I
A29: Na | B29: Se (%) | C29: Se (ppm) | D29: Se
A30: Si | B30: Al (%) | C30: Al (ppm) | D30: Al
A31: Co | D31: {=_xlfn.LET(_xlpm.value, OFFSET(INDIRECT(ADDRESS(ROW(), COLUMN())), 0, 2), IF(_xlpm.value="", "", _xlpm.value))}
A32: I | D32: {=_xlfn.LET(_xlpm.value, OFFSET(INDIRECT(ADDRESS(ROW(), COLUMN())), 0, 2), IF(_xlpm.value="", "", _xlpm.value))}
A33: Se | D33: {=_xlfn.LET(_xlpm.value, OFFSET(INDIRECT(ADDRESS(ROW(), COLUMN())), 0, 2), IF(_xlpm.value="", "", _xlpm.value))}
A34: Al | D34: {=_xlfn.LET(_xlpm.value, OFFSET(INDIRECT(ADDRESS(ROW(), COLUMN())), 0, 2), IF(_xlpm.value="", "", _xlpm.value))}
D35: {=_xlfn.LET(_xlpm.value, OFFSET(INDIRECT(ADDRESS(ROW(), COLUMN())), 0, 2), IF(_xlpm.value="", "", _xlpm.value))}

Sheet Conversions
A1: 1 ppm ≈ 1 mg/L in dilute aqueous solutions
A2: 1 mg/L * g/mol = 1/1000 µM
A3: Potassium Oxide = Potash
A9: XLOOKUP("", Conversions[Key], Conversions[Multiply By])
A10: Key | B10: Ratio | C10: To (Value) | D10: To (Unit) | E10: To | F10: To (Name) | G10: From (Value) | H10: From (Unit) | I10: From | J10: From (Name) | K10: Multiply By | L10: Notes | M10: From (Source) | N10: To (Source)
A11: =IF(Conversions[[#This Row],[From]]="", "", Conversions[[#This Row],[From]] & " (" & Conversions[[#This Row],[From (Unit)]] & ") to " & Conversions[[#This Row],[To]] & " (" & Conversions[[#This Row],[To (Unit)]] & ")") -> Al (µM) to Al (mg/L) | B11: 1 | C11: 26.982 | D11: mg/L | E11: Al | F11: Aluminum | G11: 1000 | H11: µM | I11: Al | J11: Aluminum | K11: =IF(_xlfn.SINGLE(Conversions[Key])="", "", (_xlfn.SINGLE(Conversions[Ratio]) * _xlfn.SINGLE(Conversions[To (Value)])) / _xlfn.SINGLE(Conversions[From (Value)])) -> 0.026982 | L11: ~ppm | M11: 1/1000 micromolars = 1 micrograms/L * g/mol | N11: Standard atomic weights of the elements 2021 (IUPAC Technical Report)
A12: =IF(Conversions[[#This Row],[From]]="", "", Conversions[[#This Row],[From]] & " (" & Conversions[[#This Row],[From (Unit)]] & ") to " & Conversions[[#This Row],[To]] & " (" & Conversions[[#This Row],[To (Unit)]] & ")") -> B (µM) to B (mg/L) | B12: 1 | C12: 10.81 | D12: mg/L | E12: B | F12: Boron | G12: 1000 | H12: µM | I12: B | J12: Boron | K12: =IF(_xlfn.SINGLE(Conversions[Key])="", "", (_xlfn.SINGLE(Conversions[Ratio]) * _xlfn.SINGLE(Conversions[To (Value)])) / _xlfn.SINGLE(Conversions[From (Value)])) -> 0.01081 | L12: ~ppm
A13: =IF(Conversions[[#This Row],[From]]="", "", Conversions[[#This Row],[From]] & " (" & Conversions[[#This Row],[From (Unit)]] & ") to " & Conversions[[#This Row],[To]] & " (" & Conversions[[#This Row],[To (Unit)]] & ")") -> Ca (µM) to Ca (mg/L) | B13: 1 | C13: 40.078 | D13: mg/L | E13: Ca | F13: Calcium | G13: 1000 | H13: µM | I13: Ca | J13: Calcium | K13: =IF(_xlfn.SINGLE(Conversions[Key])="", "", (_xlfn.SINGLE(Conversions[Ratio]) * _xlfn.SINGLE(Conversions[To (Value)])) / _xlfn.SINGLE(Conversions[From (Value)])) -> 0.040078 | L13: ~ppm
A14: =IF(Conversions[[#This Row],[From]]="", "", Conversions[[#This Row],[From]] & " (" & Conversions[[#This Row],[From (Unit)]] & ") to " & Conversions[[#This Row],[To]] & " (" & Conversions[[#This Row],[To (Unit)]] & ")") -> Cl (µM) to Cl (mg/L) | B14: 1 | C14: 35.45 | D14: mg/L | E14: Cl | F14: Chlorine | G14: 1000 | H14: µM | I14: Cl | J14: Chlorine | K14: =IF(_xlfn.SINGLE(Conversions[Key])="", "", (_xlfn.SINGLE(Conversions[Ratio]) * _xlfn.SINGLE(Conversions[To (Value)])) / _xlfn.SINGLE(Conversions[From (Value)])) -> 0.03545 | L14: ~ppm
A15: =IF(Conversions[[#This Row],[From]]="", "", Conversions[[#This Row],[From]] & " (" & Conversions[[#This Row],[From (Unit)]] & ") to " & Conversions[[#This Row],[To]] & " (" & Conversions[[#This Row],[To (Unit)]] & ")") -> Co (µM) to Co (mg/L) | B15: 1 | C15: 58.933 | D15: mg/L | E15: Co | F15: Cobalt | G15: 1000 | H15: µM | I15: Co | J15: Cobalt | K15: =IF(_xlfn.SINGLE(Conversions[Key])="", "", (_xlfn.SINGLE(Conversions[Ratio]) * _xlfn.SINGLE(Conversions[To (Value)])) / _xlfn.SINGLE(Conversions[From (Value)])) -> 0.058933 | L15: ~ppm
A16: =IF(Conversions[[#This Row],[From]]="", "", Conversions[[#This Row],[From]] & " (" & Conversions[[#This Row],[From (Unit)]] & ") to " & Conversions[[#This Row],[To]] & " (" & Conversions[[#This Row],[To (Unit)]] & ")") -> Cu (µM) to Cu (mg/L) | B16: 1 | C16: 63.546 | D16: mg/L | E16: Cu | F16: Copper | G16: 1000 | H16: µM | I16: Cu | J16: Copper | K16: =IF(_xlfn.SINGLE(Conversions[Key])="", "", (_xlfn.SINGLE(Conversions[Ratio]) * _xlfn.SINGLE(Conversions[To (Value)])) / _xlfn.SINGLE(Conversions[From (Value)])) -> 0.063546 | L16: ~ppm
A17: =IF(Conversions[[#This Row],[From]]="", "", Conversions[[#This Row],[From]] & " (" & Conversions[[#This Row],[From (Unit)]] & ") to " & Conversions[[#This Row],[To]] & " (" & Conversions[[#This Row],[To (Unit)]] & ")") -> Fe (µM) to Fe (mg/L) | B17: 1 | C17: 55.845 | D17: mg/L | E17: Fe | F17: Iron | G17: 1000 | H17: µM | I17: Fe | J17: Iron | K17: =IF(_xlfn.SINGLE(Conversions[Key])="", "", (_xlfn.SINGLE(Conversions[Ratio]) * _xlfn.SINGLE(Conversions[To (Value)])) / _xlfn.SINGLE(Conversions[From (Value)])) -> 0.055845 | L17: ~ppm
A18: =IF(Conversions[[#This Row],[From]]="", "", Conversions[[#This Row],[From]] & " (" & Conversions[[#This Row],[From (Unit)]] & ") to " & Conversions[[#This Row],[To]] & " (" & Conversions[[#This Row],[To (Unit)]] & ")") -> I (µM) to I (mg/L) | B18: 1 | C18: 126.904 | D18: mg/L | E18: I | F18: Iodine | G18: 1000 | H18: µM | I18: I | J18: Iodine | K18: =IF(_xlfn.SINGLE(Conversions[Key])="", "", (_xlfn.SINGLE(Conversions[Ratio]) * _xlfn.SINGLE(Conversions[To (Value)])) / _xlfn.SINGLE(Conversions[From (Value)])) -> 0.126904 | L18: ~ppm
A19: =IF(Conversions[[#This Row],[From]]="", "", Conversions[[#This Row],[From]] & " (" & Conversions[[#This Row],[From (Unit)]] & ") to " & Conversions[[#This Row],[To]] & " (" & Conversions[[#This Row],[To (Unit)]] & ")") -> K (µM) to K (mg/L) | B19: 1 | C19: 39.0983 | D19: mg/L | E19: K | F19: Potassium | G19: 1000 | H19: µM | I19: K | J19: Potassium | K19: =IF(_xlfn.SINGLE(Conversions[Key])="", "", (_xlfn.SINGLE(Conversions[Ratio]) * _xlfn.SINGLE(Conversions[To (Value)])) / _xlfn.SINGLE(Conversions[From (Value)])) -> 0.0390983 | L19: ~ppm
A20: =IF(Conversions[[#This Row],[From]]="", "", Conversions[[#This Row],[From]] & " (" & Conversions[[#This Row],[From (Unit)]] & ") to " & Conversions[[#This Row],[To]] & " (" & Conversions[[#This Row],[To (Unit)]] & ")") -> Mg (µM) to Mg (mg/L) | B20: 1 | C20: 24.305 | D20: mg/L | E20: Mg | F20: Magnesium | G20: 1000 | H20: µM | I20: Mg | J20: Magnesium | K20: =IF(_xlfn.SINGLE(Conversions[Key])="", "", (_xlfn.SINGLE(Conversions[Ratio]) * _xlfn.SINGLE(Conversions[To (Value)])) / _xlfn.SINGLE(Conversions[From (Value)])) -> 0.024305 | L20: ~ppm
A21: =IF(Conversions[[#This Row],[From]]="", "", Conversions[[#This Row],[From]] & " (" & Conversions[[#This Row],[From (Unit)]] & ") to " & Conversions[[#This Row],[To]] & " (" & Conversions[[#This Row],[To (Unit)]] & ")") -> Mn (µM) to Mn (mg/L) | B21: 1 | C21: 54.938 | D21: mg/L | E21: Mn | F21: Manganese | G21: 1000 | H21: µM | I21: Mn | J21: Manganese | K21: =IF(_xlfn.SINGLE(Conversions[Key])="", "", (_xlfn.SINGLE(Conversions[Ratio]) * _xlfn.SINGLE(Conversions[To (Value)])) / _xlfn.SINGLE(Conversions[From (Value)])) -> 0.054938 | L21: ~ppm
A22: =IF(Conversions[[#This Row],[From]]="", "", Conversions[[#This Row],[From]] & " (" & Conversions[[#This Row],[From (Unit)]] & ") to " & Conversions[[#This Row],[To]] & " (" & Conversions[[#This Row],[To (Unit)]] & ")") -> Mo (µM) to Mo (mg/L) | B22: 1 | C22: 95.95 | D22: mg/L | E22: Mo | F22: Molybdenum | G22: 1000 | H22: µM | I22: Mo | J22: Molybdenum | K22: =IF(_xlfn.SINGLE(Conversions[Key])="", "", (_xlfn.SINGLE(Conversions[Ratio]) * _xlfn.SINGLE(Conversions[To (Value)])) / _xlfn.SINGLE(Conversions[From (Value)])) -> 0.09595 | L22: ~ppm
A23: =IF(Conversions[[#This Row],[From]]="", "", Conversions[[#This Row],[From]] & " (" & Conversions[[#This Row],[From (Unit)]] & ") to " & Conversions[[#This Row],[To]] & " (" & Conversions[[#This Row],[To (Unit)]] & ")") -> N (µM) to N (mg/L) | B23: 1 | C23: 14.007 | D23: mg/L | E23: N | F23: Nitrogen | G23: 1000 | H23: µM | I23: N | J23: Nitrogen | K23: =IF(_xlfn.SINGLE(Conversions[Key])="", "", (_xlfn.SINGLE(Conversions[Ratio]) * _xlfn.SINGLE(Conversions[To (Value)])) / _xlfn.SINGLE(Conversions[From (Value)])) -> 0.014007 | L23: ~ppm
... A30: =IF(Conversions[[#This Row],[From]]="", "", Conversions[[#This Row],[From]] & " (" & Conversions[[#This Row],[From (Unit)]] & ") to " & Conversions[[#This Row],[To]] & " (" & Conversions[[#This Row],[To (Unit)]] & ")") -> Zn (µM) to Zn (mg/L) | B30: 1 | C30: 65.38 | D30: mg/L | E30: Zn | F30: Zinc | G30: 1000 | H30: µM | I30: Zn | J30: Zinc | K30: =IF(_xlfn.SINGLE(Conversions[Key])="", "", (_xlfn.SINGLE(Conversions[Ratio]) * _xlfn.SINGLE(Conversions[To (Value)])) / _xlfn.SINGLE(Conversions[From (Value)])) -> 0.06538 | L30: ~ppm
A31: =IF(Conversions[[#This Row],[From]]="", "", Conversions[[#This Row],[From]] & " (" & Conversions[[#This Row],[From (Unit)]] & ") to " & Conversions[[#This Row],[To]] & " (" & Conversions[[#This Row],[To (Unit)]] & ")") -> % (%) to ppm (ppm) | B31: 1 | C31: 10000 | D31: ppm | E31: ppm | F31: Parts-Per-Million | G31: 1 | H31: % | I31: % | J31: Percent | K31: =IF(_xlfn.SINGLE(Conversions[Key])="", "", (_xlfn.SINGLE(Conversions[Ratio]) * _xlfn.SINGLE(Conversions[To (Value)])) / _xlfn.SINGLE(Conversions[From (Value)])) -> 10000
A32: =IF(Conversions[[#This Row],[From]]="", "", Conversions[[#This Row],[From]] & " (" & Conversions[[#This Row],[From (Unit)]] & ") to " & Conversions[[#This Row],[To]] & " (" & Conversions[[#This Row],[To (Unit)]] & ")") -> K₂O (g/mol) to K (g/mol) | B32: 2 | C32: 39.1 | D32: g/mol | E32: K | F32: Potassium | G32: 94.2 | H32: g/mol | I32: K₂O | J32: Potassium Oxide | K32: =IF(_xlfn.SINGLE(Conversions[Key])="", "", (_xlfn.SINGLE(Conversions[Ratio]) * _xlfn.SINGLE(Conversions[To (Value)])) / _xlfn.SINGLE(Conversions[From (Value)])) -> 0.83014862
A33: =IF(Conversions[[#This Row],[From]]="", "", Conversions[[#This Row],[From]] & " (" & Conversions[[#This Row],[From (Unit)]] & ") to " & Conversions[[#This Row],[To]] & " (" & Conversions[[#This Row],[To (Unit)]] & ")") -> N (g/mol) to NH₄ (g/mol) | B33: 1 | C33: 18.039 | D33: g/mol | E33: NH₄ | F33: Ammonium | G33: 14.007 | H33: g/mol | I33: N | J33: Nitrogen | K33: =IF(_xlfn.SINGLE(Conversions[Key])="", "", (_xlfn.SINGLE(Conversions[Ratio]) * _xlfn.SINGLE(Conversions[To (Value)])) / _xlfn.SINGLE(Conversions[From (Value)])) -> 1.2878561
A34: =IF(Conversions[[#This Row],[From]]="", "", Conversions[[#This Row],[From]] & " (" & Conversions[[#This Row],[From (Unit)]] & ") to " & Conversions[[#This Row],[To]] & " (" & Conversions[[#This Row],[To (Unit)]] & ")") -> N (g/mol) to NO₃ (g/mol) | B34: 1 | C34: 62.004 | D34: g/mol | E34: NO₃ | F34: Nitrate | G34: 14.007 | H34: g/mol | I34: N | J34: Nitrogen | K34: =IF(_xlfn.SINGLE(Conversions[Key])="", "", (_xlfn.SINGLE(Conversions[Ratio]) * _xlfn.SINGLE(Conversions[To (Value)])) / _xlfn.SINGLE(Conversions[From (Value)])) -> 4.4266438
A35: =IF(Conversions[[#This Row],[From]]="", "", Conversions[[#This Row],[From]] & " (" & Conversions[[#This Row],[From (Unit)]] & ") to " & Conversions[[#This Row],[To]] & " (" & Conversions[[#This Row],[To (Unit)]] & ")") -> NH₄ (g/mol) to N (g/mol) | B35: 1 | C35: 14.007 | D35: g/mol | E35: N | F35: Nitrogen | G35: 18.039 | H35: g/mol | I35: NH₄ | J35: Ammonium | K35: =IF(_xlfn.SINGLE(Conversions[Key])="", "", (_xlfn.SINGLE(Conversions[Ratio]) * _xlfn.SINGLE(Conversions[To (Value)])) / _xlfn.SINGLE(Conversions[From (Value)])) -> 0.77648428
A36: =IF(Conversions[[#This Row],[From]]="", "", Conversions[[#This Row],[From]] & " (" & Conversions[[#This Row],[From (Unit)]] & ") to " & Conversions[[#This Row],[To]] & " (" & Conversions[[#This Row],[To (Unit)]] & ")") -> NO₃ (g/mol) to N (g/mol) | B36: 1 | C36: 14.007 | D36: g/mol | E36: N | F36: Nitrogen | G36: 62.004 | H36: g/mol | I36: NO₃ | J36: Nitrate | K36: =IF(_xlfn.SINGLE(Conversions[Key])="", "", (_xlfn.SINGLE(Conversions[Ratio]) * _xlfn.SINGLE(Conversions[To (Value)])) / _xlfn.SINGLE(Conversions[From (Value)])) -> 0.22590478
A37: =IF(Conversions[[#This Row],[From]]="", "", Conversions[[#This Row],[From]] & " (" & Conversions[[#This Row],[From (Unit)]] & ") to " & Conversions[[#This Row],[To]] & " (" & Conversions[[#This Row],[To (Unit)]] & ")") -> P₂O₅ (g/mol) to P (g/mol) | B37: 2 | C37: 30.97 | D37: g/mol | E37: P | F37: Phosphorus | G37: 141.94 | H37: g/mol | I37: P₂O₅ | J37: Phosphorus Pentoxide | K37: =IF(_xlfn.SINGLE(Conversions[Key])="", "", (_xlfn.SINGLE(Conversions[Ratio]) * _xlfn.SINGLE(Conversions[To (Value)])) / _xlfn.SINGLE(Conversions[From (Value)])) -> 0.43638157
A38: =IF(Conversions[[#This Row],[From]]="", "", Conversions[[#This Row],[From]] & " (" & Conversions[[#This Row],[From (Unit)]] & ") to " & Conversions[[#This Row],[To]] & " (" & Conversions[[#This Row],[To (Unit)]] & ")") -> SO₄²⁻ (g/mol) to S (g/mol) | B38: 1 | C38: 32.06 | D38: g/mol | E38: S | F38: Sulfur | G38: 96.06 | H38: g/mol | I38: SO₄²⁻ | J38: Sulfate Ion | K38: =IF(_xlfn.SINGLE(Conversions[Key])="", "", (_xlfn.SINGLE(Conversions[Ratio]) * _xlfn.SINGLE(Conversions[To (Value)])) / _xlfn.SINGLE(Conversions[From (Value)])) -> 0.33374974

Sheet Procedures
A10: Id | B10: Group | C10: Type | D10: Name | E10: Description | F10: Link to Steps
A11: 1 | B11: pH Adjustments | C11: default-ph | D11: General Hydroponics pH Up Adjustment | E11: General Hydroponics pH Up Adjustment
A12: 2 | B12: Seed Scarification | C12: default-ss | D12: 3% H2O2 Seed Scarification | E12: 3% H2O2 Seed Scarification
A13: 3 | B13: Water Sterilization | C13: default-ws | D13: Added 3% H2O2 for O2 | E13: Added 3% H2O2 for O2

Sheet Containers
D1: Cube
D2: Cylinder
D3: Vase
A10: Jar | B10: Name | C10: Volume (mL) | D10: Shape | E10: Tapered Top | F10: Outer Width (mm) | G10: Outer Height (mm) | H10: Inner Lid Diameter (mm)
A11: Half-Gallon Ball Mason Jar | B11: Half-Gallon Ball Mason Jar | C11: 1892.7 | D11: Cylinder | E11: 1
A12: Cylindrical Olive Jar | B12: Cylindrical Olive Jar | C12: 371 | D12: Cylinder | E12: 0 | F12: 69 | G12: 110 | H12: 55
A13: Jelly Jar, Cube Shape | B13: Stonewall Kitchen Wild Maine Blueberry Jam | C13: 354 | D13: Cube | E13: 1 | F13: 72 | G13: 96 | H13: 53
A14: Smucker's Sugar Free Jam Jar | B14: Smucker's Sugar Free Jam Jar | C14: 361 | D14: Cylinder | E14: 1 | F14: 70 | G14: 125 | H14: 50
A15: Dr. Schroeder's 250ml Jar | B15: Dr. Schroeder's 250ml Jar | C15: 250 | D15: Vase | E15: 1

Sheet Fertilizers
A1: All values are percentages.
J9: Nitrate | K9: Ammonium | M9: Nitrate | N9: Ammonium | O9: Urea | P9: Available Phosphate | Q9: Soluble Potash
A10: Fertilizer | B10: Updated | C10: Name | D10: Chemical Formula | E10: Hazard Statements | F10: Molar Mass (g/mol) | G10: N (%) | H10: P (%) | I10: K (%) | J10: NO₃ (%) | K10: C:NH₄ (%) | L10: Total N (%) | M10: NO₃ (%/N) | N10: NH₄ (%/N) | O10: CO(NH₂)₂ (%/N) | P10: P₂O₅ (%) | Q10: K₂O (%) | R10: Ca (%) | S10: Mg (%) | T10: S (%) | U10: B (%) | V10: Cu (%) | W10: Fe (%) | X10: Mn (%) | Y10: Mo (%) | Z10: Zn (%) | AA10: Ni (%) | AB10: Cl (%) | AC10: Na (%) | AD10: Si (%) | AE10: Co (%) | AF10: I (%) | AG10: Se (%) | AH10: Al (%)
A11: Monopotassium Phosphate | B11: 2026-10-10 | C11: Monopotassium Phosphate | D11: KH₂PO₄ | E11: Warning. Irritant: causes skin irritation, causes serious eye irritation. | F11: 136.086 | G11: =IF(Fertilizers[[#This Row],[Total N (%)]]="", "", (Fertilizers[[#This Row],[NO₃ (%)]] * _xlfn.XLOOKUP("NO₃ (g/mol) to N (g/mol)", Conversions[Key], Conversions[Multiply By]) + Fertilizers[[#This Row],[C:NH₄ (%)]] * _xlfn.XLOOKUP("NH₄ (g/mol) to N (g/mol)", Conversions[Key], Conversions[Multiply By]))) -> 0 | H11: =IF(Fertilizers[[#This Row],[P₂O₅ (%)]]="", "", Fertilizers[[#This Row],[P₂O₅ (%)]] * _xlfn.XLOOKUP("P₂O₅ (g/mol) to P (g/mol)", Conversions[Key], Conversions[Multiply By])) -> 22.757299 | I11: =IF(Fertilizers[[#This Row],[K₂O (%)]]="", "", Fertilizers[[#This Row],[K₂O (%)]] * _xlfn.XLOOKUP("K₂O (g/mol) to K (g/mol)", Conversions[Key], Conversions[Multiply By])) -> 28.731444 | J11: =IF(Fertilizers[[#This Row],[Total N (%)]]="", "", IF(Fertilizers[[#This Row],[Total N (%)]]=0, 0, Fertilizers[[#This Row],[Total N (%)]] * _xlfn.XLOOKUP("N (g/mol) to NO₃ (g/mol)", Conversions[Key], Conversions[Multiply By]) * (Fertilizers[[#This Row],[NO₃ (%/N)]] / Fertilizers[[#This Row],[Total N (%)]]))) -> 0 | K11: =IF(Fertilizers[[#This Row],[Total N (%)]]="", "", IF(Fertilizers[[#This Row],[Total N (%)]]=0, 0, Fertilizers[[#This Row],[Total N (%)]] * _xlfn.XLOOKUP("N (g/mol) to NH₄ (g/mol)", Conversions[Key], Conversions[Multiply By]) * (Fertilizers[[#This Row],[NH₄ (%/N)]] / Fertilizers[[#This Row],[Total N (%)]]))) -> 0 | L11: 0 | M11: 0 | N11: 0 | O11: 0 | P11: 52.15 | Q11: 34.61 | R11: 0 | S11: 0 | T11: 0 | U11: 0 | V11: 0 | W11: 0 | X11: 0 | Y11: 0 | Z11: 0 | AA11: 0 | AB11: 0 | AC11: 0 | AD11: 0 | AE11: 0 | AF11: 0 | AG11: 0 | AH11: 0
A12: Potassium Chloride | B12: 2026-10-10 | C12: Potassium Chloride | D12: KCl | E12: Non-Hazardous | F12: 74.55 | G12: =IF(Fertilizers[[#This Row],[Total N (%)]]="", "", (Fertilizers[[#This Row],[NO₃ (%)]] * _xlfn.XLOOKUP("NO₃ (g/mol) to N (g/mol)", Conversions[Key], Conversions[Multiply By]) + Fertilizers[[#This Row],[C:NH₄ (%)]] * _xlfn.XLOOKUP("NH₄ (g/mol) to N (g/mol)", Conversions[Key], Conversions[Multiply By]))) -> 0 | H12: =IF(Fertilizers[[#This Row],[P₂O₅ (%)]]="", "", Fertilizers[[#This Row],[P₂O₅ (%)]] * _xlfn.XLOOKUP("P₂O₅ (g/mol) to P (g/mol)", Conversions[Key], Conversions[Multiply By])) -> 0 | I12: =IF(Fertilizers[[#This Row],[K₂O (%)]]="", "", Fertilizers[[#This Row],[K₂O (%)]] * _xlfn.XLOOKUP("K₂O (g/mol) to K (g/mol)", Conversions[Key], Conversions[Multiply By])) -> 52.440488 | J12: =IF(Fertilizers[[#This Row],[Total N (%)]]="", "", IF(Fertilizers[[#This Row],[Total N (%)]]=0, 0, Fertilizers[[#This Row],[Total N (%)]] * _xlfn.XLOOKUP("N (g/mol) to NO₃ (g/mol)", Conversions[Key], Conversions[Multiply By]) * (Fertilizers[[#This Row],[NO₃ (%/N)]] / Fertilizers[[#This Row],[Total N (%)]]))) -> 0 | K12: =IF(Fertilizers[[#This Row],[Total N (%)]]="", "", IF(Fertilizers[[#This Row],[Total N (%)]]=0, 0, Fertilizers[[#This Row],[Total N (%)]] * _xlfn.XLOOKUP("N (g/mol) to NH₄ (g/mol)", Conversions[Key], Conversions[Multiply By]) * (Fertilizers[[#This Row],[NH₄ (%/N)]] / Fertilizers[[#This Row],[Total N (%)]]))) -> 0 | L12: 0 | M12: 0 | N12: 0 | O12: 0 | P12: 0 | Q12: 63.17 | R12: 0 | S12: 0 | T12: 0 | U12: 0 | V12: 0 | W12: 0 | X12: 0 | Y12: 0 | Z12: 0 | AA12: 0 | AB12: 47.55 | AC12: 0 | AD12: 0 | AE12: 0 | AF12: 0 | AG12: 0 | AH12: 0
A13: Potassium Silicate | B13: 2026-10-10 | C13: Potassium Silicate | D13: K₂SiO₃ | E13: Danger: corrosive, irritant. | F13: 154.279 | G13: =IF(Fertilizers[[#This Row],[Total N (%)]]="", "", (Fertilizers[[#This Row],[NO₃ (%)]] * _xlfn.XLOOKUP("NO₃ (g/mol) to N (g/mol)", Conversions[Key], Conversions[Multiply By]) + Fertilizers[[#This Row],[C:NH₄ (%)]] * _xlfn.XLOOKUP("NH₄ (g/mol) to N (g/mol)", Conversions[Key], Conversions[Multiply By]))) -> 0 | H13: =IF(Fertilizers[[#This Row],[P₂O₅ (%)]]="", "", Fertilizers[[#This Row],[P₂O₅ (%)]] * _xlfn.XLOOKUP("P₂O₅ (g/mol) to P (g/mol)", Conversions[Key], Conversions[Multiply By])) -> 0 | I13: =IF(Fertilizers[[#This Row],[K₂O (%)]]="", "", Fertilizers[[#This Row],[K₂O (%)]] * _xlfn.XLOOKUP("K₂O (g/mol) to K (g/mol)", Conversions[Key], Conversions[Multiply By])) -> 25.402548 | J13: =IF(Fertilizers[[#This Row],[Total N (%)]]="", "", IF(Fertilizers[[#This Row],[Total N (%)]]=0, 0, Fertilizers[[#This Row],[Total N (%)]] * _xlfn.XLOOKUP("N (g/mol) to NO₃ (g/mol)", Conversions[Key], Conversions[Multiply By]) * (Fertilizers[[#This Row],[NO₃ (%/N)]] / Fertilizers[[#This Row],[Total N (%)]]))) -> 0 | K13: =IF(Fertilizers[[#This Row],[Total N (%)]]="", "", IF(Fertilizers[[#This Row],[Total N (%)]]=0, 0, Fertilizers[[#This Row],[Total N (%)]] * _xlfn.XLOOKUP("N (g/mol) to NH₄ (g/mol)", Conversions[Key], Conversions[Multiply By]) * (Fertilizers[[#This Row],[NH₄ (%/N)]] / Fertilizers[[#This Row],[Total N (%)]]))) -> 0 | L13: 0 | M13: 0 | N13: 0 | O13: 0 | P13: 0 | Q13: 30.6 | R13: 0 | S13: 0 | T13: 0 | U13: 0 | V13: 0 | W13: 0 | X13: 0 | Y13: 0 | Z13: 0 | AA13: 0 | AB13: 0 | AC13: 0 | AD13: 18.23 | AE13: 0 | AF13: 0 | AG13: 0 | AH13: 0
A14: Potassium Sulfate | B14: 2026-10-10 | C14: Potassium Sulfate | D14: K₂SO₄ | E14: Warning: irritant. | F14: 174.25 | G14: =IF(Fertilizers[[#This Row],[Total N (%)]]="", "", (Fertilizers[[#This Row],[NO₃ (%)]] * _xlfn.XLOOKUP("NO₃ (g/mol) to N (g/mol)", Conversions[Key], Conversions[Multiply By]) + Fertilizers[[#This Row],[C:NH₄ (%)]] * _xlfn.XLOOKUP("NH₄ (g/mol) to N (g/mol)", Conversions[Key], Conversions[Multiply By]))) -> 0 | H14: =IF(Fertilizers[[#This Row],[P₂O₅ (%)]]="", "", Fertilizers[[#This Row],[P₂O₅ (%)]] * _xlfn.XLOOKUP("P₂O₅ (g/mol) to P (g/mol)", Conversions[Key], Conversions[Multiply By])) -> 0 | I14: =IF(Fertilizers[[#This Row],[K₂O (%)]]="", "", Fertilizers[[#This Row],[K₂O (%)]] * _xlfn.XLOOKUP("K₂O (g/mol) to K (g/mol)", Conversions[Key], Conversions[Multiply By])) -> 44.869533 | J14: =IF(Fertilizers[[#This Row],[Total N (%)]]="", "", IF(Fertilizers[[#This Row],[Total N (%)]]=0, 0, Fertilizers[[#This Row],[Total N (%)]] * _xlfn.XLOOKUP("N (g/mol) to NO₃ (g/mol)", Conversions[Key], Conversions[Multiply By]) * (Fertilizers[[#This Row],[NO₃ (%/N)]] / Fertilizers[[#This Row],[Total N (%)]]))) -> 0 | K14: =IF(Fertilizers[[#This Row],[Total N (%)]]="", "", IF(Fertilizers[[#This Row],[Total N (%)]]=0, 0, Fertilizers[[#This Row],[Total N (%)]] * _xlfn.XLOOKUP("N (g/mol) to NH₄ (g/mol)", Conversions[Key], Conversions[Multiply By]) * (Fertilizers[[#This Row],[NH₄ (%/N)]] / Fertilizers[[#This Row],[Total N (%)]]))) -> 0 | L14: 0 | M14: 0 | N14: 0 | O14: 0 | P14: 0 | Q14: 54.05 | R14: 0 | S14: 0 | T14: 18.4 | U14: 0 | V14: 0 | W14: 0 | X14: 0 | Y14: 0 | Z14: 0 | AA14: 0 | AB14: 0 | AC14: 0 | AD14: 0 | AE14: 0 | AF14: 0 | AG14: 0 | AH14: 0
A15: Potassium Nitrate | B15: 2026-10-10 | C15: Potassium Nitrate | D15: KNO₃ | E15: Warning: oxidizer, irritant. | F15: 101.102 | G15: =IF(Fertilizers[[#This Row],[Total N (%)]]="", "", (Fertilizers[[#This Row],[NO₃ (%)]] * _xlfn.XLOOKUP("NO₃ (g/mol) to N (g/mol)", Conversions[Key], Conversions[Multiply By]) + Fertilizers[[#This Row],[C:NH₄ (%)]] * _xlfn.XLOOKUP("NH₄ (g/mol) to N (g/mol)", Conversions[Key], Conversions[Multiply By]))) -> 13.85 | H15: =IF(Fertilizers[[#This Row],[P₂O₅ (%)]]="", "", Fertilizers[[#This Row],[P₂O₅ (%)]] * _xlfn.XLOOKUP("P₂O₅ (g/mol) to P (g/mol)", Conversions[Key], Conversions[Multiply By])) -> 0 | I15: =IF(Fertilizers[[#This Row],[K₂O (%)]]="", "", Fertilizers[[#This Row],[K₂O (%)]] * _xlfn.XLOOKUP("K₂O (g/mol) to K (g/mol)", Conversions[Key], Conversions[Multiply By])) -> 38.668323 | J15: =IF(Fertilizers[[#This Row],[Total N (%)]]="", "", IF(Fertilizers[[#This Row],[Total N (%)]]=0, 0, Fertilizers[[#This Row],[Total N (%)]] * _xlfn.XLOOKUP("N (g/mol) to NO₃ (g/mol)", Conversions[Key], Conversions[Multiply By]) * (Fertilizers[[#This Row],[NO₃ (%/N)]] / Fertilizers[[#This Row],[Total N (%)]]))) -> 61.309017 | K15: =IF(Fertilizers[[#This Row],[Total N (%)]]="", "", IF(Fertilizers[[#This Row],[Total N (%)]]=0, 0, Fertilizers[[#This Row],[Total N (%)]] * _xlfn.XLOOKUP("N (g/mol) to NH₄ (g/mol)", Conversions[Key], Conversions[Multiply By]) * (Fertilizers[[#This Row],[NH₄ (%/N)]] / Fertilizers[[#This Row],[Total N (%)]]))) -> 0 | L15: 13.85 | M15: 13.85 | N15: 0 | O15: 0 | P15: 0 | Q15: 46.58 | R15: 0 | S15: 0 | T15: 0 | U15: 0 | V15: 0 | W15: 0 | X15: 0 | Y15: 0 | Z15: 0 | AA15: 0 | AB15: 0 | AC15: 0 | AD15: 0 | AE15: 0 | AF15: 0 | AG15: 0 | AH15: 0
A16: Calcium Nitrate | B16: 2026-10-10 | C16: Calcium Nitrate Tetrahydrate | D16: Ca(NO₃)₂ · 4H₂O | E16: Danger: oxidizer, corrosive, irritant. | F16: 236.15 | G16: =IF(Fertilizers[[#This Row],[Total N (%)]]="", "", (Fertilizers[[#This Row],[NO₃ (%)]] * _xlfn.XLOOKUP("NO₃ (g/mol) to N (g/mol)", Conversions[Key], Conversions[Multiply By]) + Fertilizers[[#This Row],[C:NH₄ (%)]] * _xlfn.XLOOKUP("NH₄ (g/mol) to N (g/mol)", Conversions[Key], Conversions[Multiply By]))) -> 11.862545 | H16: =IF(Fertilizers[[#This Row],[P₂O₅ (%)]]="", "", Fertilizers[[#This Row],[P₂O₅ (%)]] * _xlfn.XLOOKUP("P₂O₅ (g/mol) to P (g/mol)", Conversions[Key], Conversions[Multiply By])) -> 0 | I16: =IF(Fertilizers[[#This Row],[K₂O (%)]]="", "", Fertilizers[[#This Row],[K₂O (%)]] * _xlfn.XLOOKUP("K₂O (g/mol) to K (g/mol)", Conversions[Key], Conversions[Multiply By])) -> 0 | J16: =IF(Fertilizers[[#This Row],[Total N (%)]]="", "", IF(Fertilizers[[#This Row],[Total N (%)]]=0, 0, Fertilizers[[#This Row],[Total N (%)]] * _xlfn.XLOOKUP("N (g/mol) to NO₃ (g/mol)", Conversions[Key], Conversions[Multiply By]) * (Fertilizers[[#This Row],[NO₃ (%/N)]] / Fertilizers[[#This Row],[Total N (%)]]))) -> 52.511261 | K16: =IF(Fertilizers[[#This Row],[Total N (%)]]="", "", IF(Fertilizers[[#This Row],[Total N (%)]]=0, 0, Fertilizers[[#This Row],[Total N (%)]] * _xlfn.XLOOKUP("N (g/mol) to NH₄ (g/mol)", Conversions[Key], Conversions[Multiply By]) * (Fertilizers[[#This Row],[NH₄ (%/N)]] / Fertilizers[[#This Row],[Total N (%)]]))) -> 0 | L16: 11.862545 | M16: 11.862545 | N16: 0 | O16: 0 | P16: 0 | Q16: 0 | R16: 16.971416 | S16: 0 | T16: 0 | U16: 0 | V16: 0 | W16: 0 | X16: 0 | Y16: 0 | Z16: 0 | AA16: 0 | AB16: 0 | AC16: 0 | AD16: 0 | AE16: 0 | AF16: 0 | AG16: 0 | AH16: 0
A17: Epsom Salt | B17: 2026-10-10 | C17: Magnesium Sulfate Heptahydrate | D17: MgSO₄ · 7H₂O | E17: Non-Hazardous | F17: 246.47 | G17: =IF(Fertilizers[[#This Row],[Total N (%)]]="", "", (Fertilizers[[#This Row],[NO₃ (%)]] * _xlfn.XLOOKUP("NO₃ (g/mol) to N (g/mol)", Conversions[Key], Conversions[Multiply By]) + Fertilizers[[#This Row],[C:NH₄ (%)]] * _xlfn.XLOOKUP("NH₄ (g/mol) to N (g/mol)", Conversions[Key], Conversions[Multiply By]))) -> 0 | H17: =IF(Fertilizers[[#This Row],[P₂O₅ (%)]]="", "", Fertilizers[[#This Row],[P₂O₅ (%)]] * _xlfn.XLOOKUP("P₂O₅ (g/mol) to P (g/mol)", Conversions[Key], Conversions[Multiply By])) -> 0 | I17: =IF(Fertilizers[[#This Row],[K₂O (%)]]="", "", Fertilizers[[#This Row],[K₂O (%)]] * _xlfn.XLOOKUP("K₂O (g/mol) to K (g/mol)", Conversions[Key], Conversions[Multiply By])) -> 0 | J17: =IF(Fertilizers[[#This Row],[Total N (%)]]="", "", IF(Fertilizers[[#This Row],[Total N (%)]]=0, 0, Fertilizers[[#This Row],[Total N (%)]] * _xlfn.XLOOKUP("N (g/mol) to NO₃ (g/mol)", Conversions[Key], Conversions[Multiply By]) * (Fertilizers[[#This Row],[NO₃ (%/N)]] / Fertilizers[[#This Row],[Total N (%)]]))) -> 0 | K17: =IF(Fertilizers[[#This Row],[Total N (%)]]="", "", IF(Fertilizers[[#This Row],[Total N (%)]]=0, 0, Fertilizers[[#This Row],[Total N (%)]] * _xlfn.XLOOKUP("N (g/mol) to NH₄ (g/mol)", Conversions[Key], Conversions[Multiply By]) * (Fertilizers[[#This Row],[NH₄ (%/N)]] / Fertilizers[[#This Row],[Total N (%)]]))) -> 0 | L17: 0 | M17: 0 | N17: 0 | O17: 0 | P17: 0 | Q17: 0 | R17: 0 | S17: 9.86 | T17: 13.01 | U17: 0 | V17: 0 | W17: 0 | X17: 0 | Y17: 0 | Z17: 0 | AA17: 0 | AB17: 0 | AC17: 0 | AD17: 0 | AE17: 0 | AF17: 0 | AG17: 0 | AH17: 0
A18: 12-4-16 | B18: 2026-10-10 | C18: Jack's Nutrients 12-4-16 RO | G18: =IF(Fertilizers[[#This Row],[Total N (%)]]="", "", (Fertilizers[[#This Row],[NO₃ (%)]] * _xlfn.XLOOKUP("NO₃ (g/mol) to N (g/mol)", Conversions[Key], Conversions[Multiply By]) + Fertilizers[[#This Row],[C:NH₄ (%)]] * _xlfn.XLOOKUP("NH₄ (g/mol) to N (g/mol)", Conversions[Key], Conversions[Multiply By]))) -> 12 | H18: =IF(Fertilizers[[#This Row],[P₂O₅ (%)]]="", "", Fertilizers[[#This Row],[P₂O₅ (%)]] * _xlfn.XLOOKUP("P₂O₅ (g/mol) to P (g/mol)", Conversions[Key], Conversions[Multiply By])) -> 1.7455263 | I18: =IF(Fertilizers[[#This Row],[K₂O (%)]]="", "", Fertilizers[[#This Row],[K₂O (%)]] * _xlfn.XLOOKUP("K₂O (g/mol) to K (g/mol)", Conversions[Key], Conversions[Multiply By])) -> 13.282378 | J18: =IF(Fertilizers[[#This Row],[Total N (%)]]="", "", IF(Fertilizers[[#This Row],[Total N (%)]]=0, 0, Fertilizers[[#This Row],[Total N (%)]] * _xlfn.XLOOKUP("N (g/mol) to NO₃ (g/mol)", Conversions[Key], Conversions[Multiply By]) * (Fertilizers[[#This Row],[NO₃ (%/N)]] / Fertilizers[[#This Row],[Total N (%)]]))) -> 52.234397 | K18: =IF(Fertilizers[[#This Row],[Total N (%)]]="", "", IF(Fertilizers[[#This Row],[Total N (%)]]=0, 0, Fertilizers[[#This Row],[Total N (%)]] * _xlfn.XLOOKUP("N (g/mol) to NH₄ (g/mol)", Conversions[Key], Conversions[Multiply By]) * (Fertilizers[[#This Row],[NH₄ (%/N)]] / Fertilizers[[#This Row],[Total N (%)]]))) -> 0.25757121 | L18: 12 | M18: 11.8 | N18: 0.2 | O18: 0 | P18: 4 | Q18: 16 | R18: 7 | S18: 2 | T18: 0 | U18: 0.02 | V18: 0.02 | W18: 0.15 | X18: 0.05 | Y18: 0.001 | Z18: 0.035 | AA18: 0 | AB18: 0 | AC18: 0 | AD18: 0 | AE18: 0 | AF18: 0 | AG18: 0 | AH18: 0
A19: 10-5-14 | B19: 2026-10-10 | C19: GH MaxiGro 10-5-14 | G19: =IF(Fertilizers[[#This Row],[Total N (%)]]="", "", (Fertilizers[[#This Row],[NO₃ (%)]] * _xlfn.XLOOKUP("NO₃ (g/mol) to N (g/mol)", Conversions[Key], Conversions[Multiply By]) + Fertilizers[[#This Row],[C:NH₄ (%)]] * _xlfn.XLOOKUP("NH₄ (g/mol) to N (g/mol)", Conversions[Key], Conversions[Multiply By]))) -> 10 | H19: =IF(Fertilizers[[#This Row],[P₂O₅ (%)]]="", "", Fertilizers[[#This Row],[P₂O₅ (%)]] * _xlfn.XLOOKUP("P₂O₅ (g/mol) to P (g/mol)", Conversions[Key], Conversions[Multiply By])) -> 2.1819078 | I19: =IF(Fertilizers[[#This Row],[K₂O (%)]]="", "", Fertilizers[[#This Row],[K₂O (%)]] * _xlfn.XLOOKUP("K₂O (g/mol) to K (g/mol)", Conversions[Key], Conversions[Multiply By])) -> 11.622081 | J19: =IF(Fertilizers[[#This Row],[Total N (%)]]="", "", IF(Fertilizers[[#This Row],[Total N (%)]]=0, 0, Fertilizers[[#This Row],[Total N (%)]] * _xlfn.XLOOKUP("N (g/mol) to NO₃ (g/mol)", Conversions[Key], Conversions[Multiply By]) * (Fertilizers[[#This Row],[NO₃ (%/N)]] / Fertilizers[[#This Row],[Total N (%)]]))) -> 37.626472 | K19: =IF(Fertilizers[[#This Row],[Total N (%)]]="", "", IF(Fertilizers[[#This Row],[Total N (%)]]=0, 0, Fertilizers[[#This Row],[Total N (%)]] * _xlfn.XLOOKUP("N (g/mol) to NH₄ (g/mol)", Conversions[Key], Conversions[Multiply By]) * (Fertilizers[[#This Row],[NH₄ (%/N)]] / Fertilizers[[#This Row],[Total N (%)]]))) -> 1.9317841 | L19: 10 | M19: 8.5 | N19: 1.5 | O19: 0 | P19: 5 | Q19: 14 | R19: 6 | S19: 2 | T19: 3 | U19: 0 | V19: 0 | W19: 0.12 | X19: 0.05 | Y19: 0 | Z19: 0 | AA19: 0 | AB19: 0 | AC19: 0 | AD19: 0 | AE19: 0 | AF19: 0 | AG19: 0 | AH19: 0
G20: =IF(Fertilizers[[#This Row],[Total N (%)]]="", "", (Fertilizers[[#This Row],[NO₃ (%)]] * _xlfn.XLOOKUP("NO₃ (g/mol) to N (g/mol)", Conversions[Key], Conversions[Multiply By]) + Fertilizers[[#This Row],[C:NH₄ (%)]] * _xlfn.XLOOKUP("NH₄ (g/mol) to N (g/mol)", Conversions[Key], Conversions[Multiply By]))) | H20: =IF(Fertilizers[[#This Row],[P₂O₅ (%)]]="", "", Fertilizers[[#This Row],[P₂O₅ (%)]] * _xlfn.XLOOKUP("P₂O₅ (g/mol) to P (g/mol)", Conversions[Key], Conversions[Multiply By])) | I20: =IF(Fertilizers[[#This Row],[K₂O (%)]]="", "", Fertilizers[[#This Row],[K₂O (%)]] * _xlfn.XLOOKUP("K₂O (g/mol) to K (g/mol)", Conversions[Key], Conversions[Multiply By])) | J20: =IF(Fertilizers[[#This Row],[Total N (%)]]="", "", IF(Fertilizers[[#This Row],[Total N (%)]]=0, 0, Fertilizers[[#This Row],[Total N (%)]] * _xlfn.XLOOKUP("N (g/mol) to NO₃ (g/mol)", Conversions[Key], Conversions[Multiply By]) * (Fertilizers[[#This Row],[NO₃ (%/N)]] / Fertilizers[[#This Row],[Total N (%)]]))) | K20: =IF(Fertilizers[[#This Row],[Total N (%)]]="", "", IF(Fertilizers[[#This Row],[Total N (%)]]=0, 0, Fertilizers[[#This Row],[Total N (%)]] * _xlfn.XLOOKUP("N (g/mol) to NH₄ (g/mol)", Conversions[Key], Conversions[Multiply By]) * (Fertilizers[[#This Row],[NH₄ (%/N)]] / Fertilizers[[#This Row],[Total N (%)]])))
G21: =IF(Fertilizers[[#This Row],[Total N (%)]]="", "", (Fertilizers[[#This Row],[NO₃ (%)]] * _xlfn.XLOOKUP("NO₃ (g/mol) to N (g/mol)", Conversions[Key], Conversions[Multiply By]) + Fertilizers[[#This Row],[C:NH₄ (%)]] * _xlfn.XLOOKUP("NH₄ (g/mol) to N (g/mol)", Conversions[Key], Conversions[Multiply By]))) | H21: =IF(Fertilizers[[#This Row],[P₂O₅ (%)]]="", "", Fertilizers[[#This Row],[P₂O₅ (%)]] * _xlfn.XLOOKUP("P₂O₅ (g/mol) to P (g/mol)", Conversions[Key], Conversions[Multiply By])) | I21: =IF(Fertilizers[[#This Row],[K₂O (%)]]="", "", Fertilizers[[#This Row],[K₂O (%)]] * _xlfn.XLOOKUP("K₂O (g/mol) to K (g/mol)", Conversions[Key], Conversions[Multiply By])) | J21: =IF(Fertilizers[[#This Row],[Total N (%)]]="", "", IF(Fertilizers[[#This Row],[Total N (%)]]=0, 0, Fertilizers[[#This Row],[Total N (%)]] * _xlfn.XLOOKUP("N (g/mol) to NO₃ (g/mol)", Conversions[Key], Conversions[Multiply By]) * (Fertilizers[[#This Row],[NO₃ (%/N)]] / Fertilizers[[#This Row],[Total N (%)]]))) | K21: =IF(Fertilizers[[#This Row],[Total N (%)]]="", "", IF(Fertilizers[[#This Row],[Total N (%)]]=0, 0, Fertilizers[[#This Row],[Total N (%)]] * _xlfn.XLOOKUP("N (g/mol) to NH₄ (g/mol)", Conversions[Key], Conversions[Multiply By]) * (Fertilizers[[#This Row],[NH₄ (%/N)]] / Fertilizers[[#This Row],[Total N (%)]])))
G22: =IF(Fertilizers[[#This Row],[Total N (%)]]="", "", (Fertilizers[[#This Row],[NO₃ (%)]] * _xlfn.XLOOKUP("NO₃ (g/mol) to N (g/mol)", Conversions[Key], Conversions[Multiply By]) + Fertilizers[[#This Row],[C:NH₄ (%)]] * _xlfn.XLOOKUP("NH₄ (g/mol) to N (g/mol)", Conversions[Key], Conversions[Multiply By]))) | H22: =IF(Fertilizers[[#This Row],[P₂O₅ (%)]]="", "", Fertilizers[[#This Row],[P₂O₅ (%)]] * _xlfn.XLOOKUP("P₂O₅ (g/mol) to P (g/mol)", Conversions[Key], Conversions[Multiply By])) | I22: =IF(Fertilizers[[#This Row],[K₂O (%)]]="", "", Fertilizers[[#This Row],[K₂O (%)]] * _xlfn.XLOOKUP("K₂O (g/mol) to K (g/mol)", Conversions[Key], Conversions[Multiply By])) | J22: =IF(Fertilizers[[#This Row],[Total N (%)]]="", "", IF(Fertilizers[[#This Row],[Total N (%)]]=0, 0, Fertilizers[[#This Row],[Total N (%)]] * _xlfn.XLOOKUP("N (g/mol) to NO₃ (g/mol)", Conversions[Key], Conversions[Multiply By]) * (Fertilizers[[#This Row],[NO₃ (%/N)]] / Fertilizers[[#This Row],[Total N (%)]]))) | K22: =IF(Fertilizers[[#This Row],[Total N (%)]]="", "", IF(Fertilizers[[#This Row],[Total N (%)]]=0, 0, Fertilizers[[#This Row],[Total N (%)]] * _xlfn.XLOOKUP("N (g/mol) to NH₄ (g/mol)", Conversions[Key], Conversions[Multiply By]) * (Fertilizers[[#This Row],[NH₄ (%/N)]] / Fertilizers[[#This Row],[Total N (%)]])))
G23: =IF(Fertilizers[[#This Row],[Total N (%)]]="", "", (Fertilizers[[#This Row],[NO₃ (%)]] * _xlfn.XLOOKUP("NO₃ (g/mol) to N (g/mol)", Conversions[Key], Conversions[Multiply By]) + Fertilizers[[#This Row],[C:NH₄ (%)]] * _xlfn.XLOOKUP("NH₄ (g/mol) to N (g/mol)", Conversions[Key], Conversions[Multiply By]))) | H23: =IF(Fertilizers[[#This Row],[P₂O₅ (%)]]="", "", Fertilizers[[#This Row],[P₂O₅ (%)]] * _xlfn.XLOOKUP("P₂O₅ (g/mol) to P (g/mol)", Conversions[Key], Conversions[Multiply By])) | I23: =IF(Fertilizers[[#This Row],[K₂O (%)]]="", "", Fertilizers[[#This Row],[K₂O (%)]] * _xlfn.XLOOKUP("K₂O (g/mol) to K (g/mol)", Conversions[Key], Conversions[Multiply By])) | J23: =IF(Fertilizers[[#This Row],[Total N (%)]]="", "", IF(Fertilizers[[#This Row],[Total N (%)]]=0, 0, Fertilizers[[#This Row],[Total N (%)]] * _xlfn.XLOOKUP("N (g/mol) to NO₃ (g/mol)", Conversions[Key], Conversions[Multiply By]) * (Fertilizers[[#This Row],[NO₃ (%/N)]] / Fertilizers[[#This Row],[Total N (%)]]))) | K23: =IF(Fertilizers[[#This Row],[Total N (%)]]="", "", IF(Fertilizers[[#This Row],[Total N (%)]]=0, 0, Fertilizers[[#This Row],[Total N (%)]] * _xlfn.XLOOKUP("N (g/mol) to NH₄ (g/mol)", Conversions[Key], Conversions[Multiply By]) * (Fertilizers[[#This Row],[NH₄ (%/N)]] / Fertilizers[[#This Row],[Total N (%)]])))
G24: =IF(Fertilizers[[#This Row],[Total N (%)]]="", "", (Fertilizers[[#This Row],[NO₃ (%)]] * _xlfn.XLOOKUP("NO₃ (g/mol) to N (g/mol)", Conversions[Key], Conversions[Multiply By]) + Fertilizers[[#This Row],[C:NH₄ (%)]] * _xlfn.XLOOKUP("NH₄ (g/mol) to N (g/mol)", Conversions[Key], Conversions[Multiply By]))) | H24: =IF(Fertilizers[[#This Row],[P₂O₅ (%)]]="", "", Fertilizers[[#This Row],[P₂O₅ (%)]] * _xlfn.XLOOKUP("P₂O₅ (g/mol) to P (g/mol)", Conversions[Key], Conversions[Multiply By])) | I24: =IF(Fertilizers[[#This Row],[K₂O (%)]]="", "", Fertilizers[[#This Row],[K₂O (%)]] * _xlfn.XLOOKUP("K₂O (g/mol) to K (g/mol)", Conversions[Key], Conversions[Multiply By])) | J24: =IF(Fertilizers[[#This Row],[Total N (%)]]="", "", IF(Fertilizers[[#This Row],[Total N (%)]]=0, 0, Fertilizers[[#This Row],[Total N (%)]] * _xlfn.XLOOKUP("N (g/mol) to NO₃ (g/mol)", Conversions[Key], Conversions[Multiply By]) * (Fertilizers[[#This Row],[NO₃ (%/N)]] / Fertilizers[[#This Row],[Total N (%)]]))) | K24: =IF(Fertilizers[[#This Row],[Total N (%)]]="", "", IF(Fertilizers[[#This Row],[Total N (%)]]=0, 0, Fertilizers[[#This Row],[Total N (%)]] * _xlfn.XLOOKUP("N (g/mol) to NH₄ (g/mol)", Conversions[Key], Conversions[Multiply By]) * (Fertilizers[[#This Row],[NH₄ (%/N)]] / Fertilizers[[#This Row],[Total N (%)]])))

Sheet Solutions
H9: Nitrogen | I9: Phosphorus | J9: Potassium | K9: Calcium | L9: Magnesium | M9: Sulfur | N9: Iron | O9: Manganese | P9: Zinc | Q9: Boron | R9: Copper | S9: Molybdenum | T9: Nickel | U9: Chlorine | V9: Silicone | W9: Iodine | X9: Selenium | Y9: Cobalt | Z9: Aluminum | AA9: Sodium
A10: Name | B10: Source | C10: Unit | D10: EC (min) | E10: EC (max) | F10: pH (min) | G10: pH (max) | H10: N | I10: P | J10: K | K10: Ca | L10: Mg | M10: S | N10: Fe | O10: Mn | P10: Zn | Q10: B | R10: Cu | S10: Mo | T10: Ni | U10: Cl | V10: Si | W10: I | X10: Se | Y10: Co | Z10: Al | AA10: Na | AB10: Notes
A11: Modified Sonneveld's Solution | B11: Modified Sonneveld's Solution from Mattson N. & Peters, C. "A Recipe for Hydroponic Success" | C11: ppm | H11: 150 | I11: 31 | J11: 210 | K11: 90 | L11: 24 | N11: 1 | O11: 0.25 | P11: 0.13 | Q11: 0.16 | R11: 0.023 | S11: 0.024

Sheet Nutrients
A10: For | B10: Solution | C10: Season | D10: Active | E10: EC (min) | F10: EC (max) | G10: pH (min) | H10: pH (max) | I10: N | J10: P | K10: K | L10: Ca | M10: Mg | N10: S | O10: Fe | P10: Mn | Q10: Zn | R10: B | S10: Cu | T10: Mo | U10: Ni | V10: Cl | W10: Na | X10: Si | Y10: Co | Z10: I | AA10: Se | AB10: Al | AC10: Notes | AE10: For | AF10: Nutrient | AG10: Adjust By | AH10: Notes | AI10: Source
A11: Ocimum basilicum | B11: Modified Sonneveld's Solution | C11: Year-Round | D11: 1 | E11: =IFERROR(IF(Nutrients[[#This Row],[Solution]]="","",IF(AND(_xlfn.XLOOKUP(Nutrients[[#This Row],[Solution]],Solutions[Name],Solutions[EC (min)],"")="",COUNTIFS(Adjustments[For],Nutrients[[#This Row],[For]],Adjustments[Nutrient],"EC (min)")=0),"",IFERROR(VALUE(_xlfn.XLOOKUP(Nutrients[[#This Row],[Solution]],Solutions[Name],Solutions[EC (min)],"")),0)+SUMIFS(Adjustments[Adjust By],Adjustments[For],Nutrients[[#This Row],[For]],Adjustments[Nutrient],"EC (min)"))),"") -> 0.5 | F11: =IFERROR(IF(Nutrients[[#This Row],[Solution]]="","",IF(AND(_xlfn.XLOOKUP(Nutrients[[#This Row],[Solution]],Solutions[Name],Solutions[EC (max)],"")="",COUNTIFS(Adjustments[For],Nutrients[[#This Row],[For]],Adjustments[Nutrient],"EC (max)")=0),"",IFERROR(VALUE(_xlfn.XLOOKUP(Nutrients[[#This Row],[Solution]],Solutions[Name],Solutions[EC (max)],"")),0)+SUMIFS(Adjustments[Adjust By],Adjustments[For],Nutrients[[#This Row],[For]],Adjustments[Nutrient],"EC (max)"))),"") -> 1.5 | G11: =IFERROR(IF(Nutrients[[#This Row],[Solution]]="","",IF(AND(_xlfn.XLOOKUP(Nutrients[[#This Row],[Solution]],Solutions[Name],Solutions[pH (min)],"")="",COUNTIFS(Adjustments[For],Nutrients[[#This Row],[For]],Adjustments[Nutrient],"pH (min)")=0),"",IFERROR(VALUE(_xlfn.XLOOKUP(Nutrients[[#This Row],[Solution]],Solutions[Name],Solutions[pH (min)],"")),0)+SUMIFS(Adjustments[Adjust By],Adjustments[For],Nutrients[[#This Row],[For]],Adjustments[Nutrient],"pH (min)"))),"") -> 5.8 | H11: =IFERROR(IF(Nutrients[[#This Row],[Solution]]="","",IF(AND(_xlfn.XLOOKUP(Nutrients[[#This Row],[Solution]],Solutions[Name],Solutions[pH (max)],"")="",COUNTIFS(Adjustments[For],Nutrients[[#This Row],[For]],Adjustments[Nutrient],"pH (max)")=0),"",IFERROR(VALUE(_xlfn.XLOOKUP(Nutrients[[#This Row],[Solution]],Solutions[Name],Solutions[pH (max)],"")),0)+SUMIFS(Adjustments[Adjust By],Adjustments[For],Nutrients[[#This Row],[For]],Adjustments[Nutrient],"pH (max)"))),"") -> 6.2 | I11: =IFERROR(IF(Nutrients[[#This Row],[Solution]]="","",IF(AND(_xlfn.XLOOKUP(Nutrients[[#This Row],[Solution]],Solutions[Name],Solutions[N],"")="",COUNTIFS(Adjustments[For],Nutrients[[#This Row],[For]],Adjustments[Nutrient],"N")=0),"",IFERROR(VALUE(_xlfn.XLOOKUP(Nutrients[[#This Row],[Solution]],Solutions[Name],Solutions[N],"")),0)+SUMIFS(Adjustments[Adjust By],Adjustments[For],Nutrients[[#This Row],[For]],Adjustments[Nutrient],"N"))),"") -> 150 | J11: =IFERROR(IF(Nutrients[[#This Row],[Solution]]="","",IF(AND(_xlfn.XLOOKUP(Nutrients[[#This Row],[Solution]],Solutions[Name],Solutions[P],"")="",COUNTIFS(Adjustments[For],Nutrients[[#This Row],[For]],Adjustments[Nutrient],"P")=0),"",IFERROR(VALUE(_xlfn.XLOOKUP(Nutrients[[#This Row],[Solution]],Solutions[Name],Solutions[P],"")),0)+SUMIFS(Adjustments[Adjust By],Adjustments[For],Nutrients[[#This Row],[For]],Adjustments[Nutrient],"P"))),"") -> 31 | K11: =IFERROR(IF(Nutrients[[#This Row],[Solution]]="","",IF(AND(_xlfn.XLOOKUP(Nutrients[[#This Row],[Solution]],Solutions[Name],Solutions[K],"")="",COUNTIFS(Adjustments[For],Nutrients[[#This Row],[For]],Adjustments[Nutrient],"K")=0),"",IFERROR(VALUE(_xlfn.XLOOKUP(Nutrients[[#This Row],[Solution]],Solutions[Name],Solutions[K],"")),0)+SUMIFS(Adjustments[Adjust By],Adjustments[For],Nutrients[[#This Row],[For]],Adjustments[Nutrient],"K"))),"") -> 210 | L11: =IFERROR(IF(Nutrients[[#This Row],[Solution]]="","",IF(AND(_xlfn.XLOOKUP(Nutrients[[#This Row],[Solution]],Solutions[Name],Solutions[Ca],"")="",COUNTIFS(Adjustments[For],Nutrients[[#This Row],[For]],Adjustments[Nutrient],"Ca")=0),"",IFERROR(VALUE(_xlfn.XLOOKUP(Nutrients[[#This Row],[Solution]],Solutions[Name],Solutions[Ca],"")),0)+SUMIFS(Adjustments[Adjust By],Adjustments[For],Nutrients[[#This Row],[For]],Adjustments[Nutrient],"Ca"))),"") -> 90 | M11: =IFERROR(IF(Nutrients[[#This Row],[Solution]]="","",IF(AND(_xlfn.XLOOKUP(Nutrients[[#This Row],[Solution]],Solutions[Name],Solutions[Mg],"")="",COUNTIFS(Adjustments[For],Nutrients[[#This Row],[For]],Adjustments[Nutrient],"Mg")=0),"",IFERROR(VALUE(_xlfn.XLOOKUP(Nutrients[[#This Row],[Solution]],Solutions[Name],Solutions[Mg],"")),0)+SUMIFS(Adjustments[Adjust By],Adjustments[For],Nutrients[[#This Row],[For]],Adjustments[Nutrient],"Mg"))),"") -> 24 | N11: =IFERROR(IF(Nutrients[[#This Row],[Solution]]="","",IF(AND(_xlfn.XLOOKUP(Nutrients[[#This Row],[Solution]],Solutions[Name],Solutions[S],"")="",COUNTIFS(Adjustments[For],Nutrients[[#This Row],[For]],Adjustments[Nutrient],"S")=0),"",IFERROR(VALUE(_xlfn.XLOOKUP(Nutrients[[#This Row],[Solution]],Solutions[Name],Solutions[S],"")),0)+SUMIFS(Adjustments[Adjust By],Adjustments[For],Nutrients[[#This Row],[For]],Adjustments[Nutrient],"S"))),"") -> 32 | O11: =IFERROR(IF(Nutrients[[#This Row],[Solution]]="","",IF(AND(_xlfn.XLOOKUP(Nutrients[[#This Row],[Solution]],Solutions[Name],Solutions[Fe],"")="",COUNTIFS(Adjustments[For],Nutrients[[#This Row],[For]],Adjustments[Nutrient],"Fe")=0),"",IFERROR(VALUE(_xlfn.XLOOKUP(Nutrients[[#This Row],[Solution]],Solutions[Name],Solutions[Fe],"")),0)+SUMIFS(Adjustments[Adjust By],Adjustments[For],Nutrients[[#This Row],[For]],Adjustments[Nutrient],"Fe"))),"") -> 1 | P11: =IFERROR(IF(Nutrients[[#This Row],[Solution]]="","",IF(AND(_xlfn.XLOOKUP(Nutrients[[#This Row],[Solution]],Solutions[Name],Solutions[Mn],"")="",COUNTIFS(Adjustments[For],Nutrients[[#This Row],[For]],Adjustments[Nutrient],"Mn")=0),"",IFERROR(VALUE(_xlfn.XLOOKUP(Nutrients[[#This Row],[Solution]],Solutions[Name],Solutions[Mn],"")),0)+SUMIFS(Adjustments[Adjust By],Adjustments[For],Nutrients[[#This Row],[For]],Adjustments[Nutrient],"Mn"))),"") -> 0.25 | Q11: =IFERROR(IF(Nutrients[[#This Row],[Solution]]="","",IF(AND(_xlfn.XLOOKUP(Nutrients[[#This Row],[Solution]],Solutions[Name],Solutions[Zn],"")="",COUNTIFS(Adjustments[For],Nutrients[[#This Row],[For]],Adjustments[Nutrient],"Zn")=0),"",IFERROR(VALUE(_xlfn.XLOOKUP(Nutrients[[#This Row],[Solution]],Solutions[Name],Solutions[Zn],"")),0)+SUMIFS(Adjustments[Adjust By],Adjustments[For],Nutrients[[#This Row],[For]],Adjustments[Nutrient],"Zn"))),"") -> 0.13 | R11: =IFERROR(IF(Nutrients[[#This Row],[Solution]]="","",IF(AND(_xlfn.XLOOKUP(Nutrients[[#This Row],[Solution]],Solutions[Name],Solutions[B],"")="",COUNTIFS(Adjustments[For],Nutrients[[#This Row],[For]],Adjustments[Nutrient],"B")=0),"",IFERROR(VALUE(_xlfn.XLOOKUP(Nutrients[[#This Row],[Solution]],Solutions[Name],Solutions[B],"")),0)+SUMIFS(Adjustments[Adjust By],Adjustments[For],Nutrients[[#This Row],[For]],Adjustments[Nutrient],"B"))),"") -> 0.16 | S11: =IFERROR(IF(Nutrients[[#This Row],[Solution]]="","",IF(AND(_xlfn.XLOOKUP(Nutrients[[#This Row],[Solution]],Solutions[Name],Solutions[Cu],"")="",COUNTIFS(Adjustments[For],Nutrients[[#This Row],[For]],Adjustments[Nutrient],"Cu")=0),"",IFERROR(VALUE(_xlfn.XLOOKUP(Nutrients[[#This Row],[Solution]],Solutions[Name],Solutions[Cu],"")),0)+SUMIFS(Adjustments[Adjust By],Adjustments[For],Nutrients[[#This Row],[For]],Adjustments[Nutrient],"Cu"))),"") -> 0.023 | T11: =IFERROR(IF(Nutrients[[#This Row],[Solution]]="","",IF(AND(_xlfn.XLOOKUP(Nutrients[[#This Row],[Solution]],Solutions[Name],Solutions[Mo],"")="",COUNTIFS(Adjustments[For],Nutrients[[#This Row],[For]],Adjustments[Nutrient],"Mo")=0),"",IFERROR(VALUE(_xlfn.XLOOKUP(Nutrients[[#This Row],[Solution]],Solutions[Name],Solutions[Mo],"")),0)+SUMIFS(Adjustments[Adjust By],Adjustments[For],Nutrients[[#This Row],[For]],Adjustments[Nutrient],"Mo"))),"") -> 0.024 | U11: =IFERROR(IF(Nutrients[[#This Row],[Solution]]="","",IF(AND(_xlfn.XLOOKUP(Nutrients[[#This Row],[Solution]],Solutions[Name],Solutions[Ni],"")="",COUNTIFS(Adjustments[For],Nutrients[[#This Row],[For]],Adjustments[Nutrient],"Ni")=0),"",IFERROR(VALUE(_xlfn.XLOOKUP(Nutrients[[#This Row],[Solution]],Solutions[Name],Solutions[Ni],"")),0)+SUMIFS(Adjustments[Adjust By],Adjustments[For],Nutrients[[#This Row],[For]],Adjustments[Nutrient],"Ni"))),"") -> 0.03 | V11: =IFERROR(IF(Nutrients[[#This Row],[Solution]]="","",IF(AND(_xlfn.XLOOKUP(Nutrients[[#This Row],[Solution]],Solutions[Name],Solutions[Cl],"")="",COUNTIFS(Adjustments[For],Nutrients[[#This Row],[For]],Adjustments[Nutrient],"Cl")=0),"",IFERROR(VALUE(_xlfn.XLOOKUP(Nutrients[[#This Row],[Solution]],Solutions[Name],Solutions[Cl],"")),0)+SUMIFS(Adjustments[Adjust By],Adjustments[For],Nutrients[[#This Row],[For]],Adjustments[Nutrient],"Cl"))),"") -> 1.77 | W11: =IFERROR(IF(Nutrients[[#This Row],[Solution]]="","",IF(AND(_xlfn.XLOOKUP(Nutrients[[#This Row],[Solution]],Solutions[Name],Solutions[Na],"")="",COUNTIFS(Adjustments[For],Nutrients[[#This Row],[For]],Adjustments[Nutrient],"Na")=0),"",IFERROR(VALUE(_xlfn.XLOOKUP(Nutrients[[#This Row],[Solution]],Solutions[Name],Solutions[Na],"")),0)+SUMIFS(Adjustments[Adjust By],Adjustments[For],Nutrients[[#This Row],[For]],Adjustments[Nutrient],"Na"))),"") | X11: =IFERROR(IF(Nutrients[[#This Row],[Solution]]="","",IF(AND(_xlfn.XLOOKUP(Nutrients[[#This Row],[Solution]],Solutions[Name],Solutions[Si],"")="",COUNTIFS(Adjustments[For],Nutrients[[#This Row],[For]],Adjustments[Nutrient],"Si")=0),"",IFERROR(VALUE(_xlfn.XLOOKUP(Nutrients[[#This Row],[Solution]],Solutions[Name],Solutions[Si],"")),0)+SUMIFS(Adjustments[Adjust By],Adjustments[For],Nutrients[[#This Row],[For]],Adjustments[Nutrient],"Si"))),"") -> 28 | Y11: =IFERROR(IF(Nutrients[[#This Row],[Solution]]="","",IF(AND(_xlfn.XLOOKUP(Nutrients[[#This Row],[Solution]],Solutions[Name],Solutions[Co],"")="",COUNTIFS(Adjustments[For],Nutrients[[#This Row],[For]],Adjustments[Nutrient],"Co")=0),"",IFERROR(VALUE(_xlfn.XLOOKUP(Nutrients[[#This Row],[Solution]],Solutions[Name],Solutions[Co],"")),0)+SUMIFS(Adjustments[Adjust By],Adjustments[For],Nutrients[[#This Row],[For]],Adjustments[Nutrient],"Co"))),"") | Z11: =IFERROR(IF(Nutrients[[#This Row],[Solution]]="","",IF(AND(_xlfn.XLOOKUP(Nutrients[[#This Row],[Solution]],Solutions[Name],Solutions[I],"")="",COUNTIFS(Adjustments[For],Nutrients[[#This Row],[For]],Adjustments[Nutrient],"I")=0),"",IFERROR(VALUE(_xlfn.XLOOKUP(Nutrients[[#This Row],[Solution]],Solutions[Name],Solutions[I],"")),0)+SUMIFS(Adjustments[Adjust By],Adjustments[For],Nutrients[[#This Row],[For]],Adjustments[Nutrient],"I"))),"") | AA11: =IFERROR(IF(Nutrients[[#This Row],[Solution]]="","",IF(AND(_xlfn.XLOOKUP(Nutrients[[#This Row],[Solution]],Solutions[Name],Solutions[Se],"")="",COUNTIFS(Adjustments[For],Nutrients[[#This Row],[For]],Adjustments[Nutrient],"Se")=0),"",IFERROR(VALUE(_xlfn.XLOOKUP(Nutrients[[#This Row],[Solution]],Solutions[Name],Solutions[Se],"")),0)+SUMIFS(Adjustments[Adjust By],Adjustments[For],Nutrients[[#This Row],[For]],Adjustments[Nutrient],"Se"))),"") | AB11: =IFERROR(IF(Nutrients[[#This Row],[Solution]]="","",IF(AND(_xlfn.XLOOKUP(Nutrients[[#This Row],[Solution]],Solutions[Name],Solutions[Al],"")="",COUNTIFS(Adjustments[For],Nutrients[[#This Row],[For]],Adjustments[Nutrient],"Al")=0),"",IFERROR(VALUE(_xlfn.XLOOKUP(Nutrients[[#This Row],[Solution]],Solutions[Name],Solutions[Al],"")),0)+SUMIFS(Adjustments[Adjust By],Adjustments[For],Nutrients[[#This Row],[For]],Adjustments[Nutrient],"Al"))),"") | AE11: Ocimum basilicum | AF11: Cl | AG11: 1.77 | AI11: Modified Hoagland nutrient solution from Taiz et al. 2022 "Plant Physiology and Development"
